<?xml version="1.0" encoding="utf-8"?>
<!-- =================================================================================== -->
<!-- |    This document was autogenerated by xacro from mpo_500.urdf.xacro             | -->
<!-- |    EDITING THIS FILE BY HAND IS NOT RECOMMENDED                                 | -->
<!-- =================================================================================== -->
<robot name="mpo_500">
  <!-- Lidar sensors -->
  <gazebo reference="lidar_1_link">
    <sensor name="lidar_1_sensor" type="ray">
      <pose>0 0 0 0 0 0</pose>
      <visualize>false</visualize>
      <update_rate>40</update_rate>
      <ray>
        <scan>
          <horizontal>
            <samples>720</samples>
            <resolution>1</resolution>
            <min_angle>-1.48353</min_angle>
            <max_angle>1.48353</max_angle>
          </horizontal>
        </scan>
        <range>
          <min>0.10</min>
          <max>30.0</max>
          <resolution>0.05</resolution>
        </range>
        <noise>
          <type>gaussian</type>
          <!-- Noise parameters based on published spec for Hokuyo laser
                   achieving "+-30mm" accuracy at range < 10m.  A mean of 0.0m and
                   stddev of 0.01m will put 99.7% of samples within 0.03m of the true
                   reading. -->
          <mean>0.0</mean>
          <stddev>0.01</stddev>
        </noise>
      </ray>
      <plugin filename="libgazebo_ros_laser.so" name="lidar_1">
        <topicName>lidar_1/scan_filtered</topicName>
        <frameName>lidar_1_link</frameName>
      </plugin>
    </sensor>
  </gazebo>
  <gazebo reference="lidar_2_link">
    <sensor name="lidar_2_sensor" type="ray">
      <pose>0 0 0 0 0 0</pose>
      <visualize>false</visualize>
      <update_rate>40</update_rate>
      <ray>
        <scan>
          <horizontal>
            <samples>720</samples>
            <resolution>1</resolution>
            <min_angle>-1.48353</min_angle>
            <max_angle>1.48353</max_angle>
          </horizontal>
        </scan>
        <range>
          <min>0.10</min>
          <max>30.0</max>
          <resolution>0.05</resolution>
        </range>
        <noise>
          <type>gaussian</type>
          <!-- Noise parameters based on published spec for Hokuyo laser
                   achieving "+-30mm" accuracy at range < 10m.  A mean of 0.0m and
                   stddev of 0.01m will put 99.7% of samples within 0.03m of the true
                   reading. -->
          <mean>0.0</mean>
          <stddev>0.01</stddev>
        </noise>
      </ray>
      <plugin filename="libgazebo_ros_laser.so" name="lidar_2">
        <topicName>lidar_2/scan_filtered</topicName>
        <frameName>lidar_2_link</frameName>
      </plugin>
    </sensor>
  </gazebo>
  <!-- Camera -->
  <gazebo reference="kinect_link">
    <sensor name="camera_1" type="depth">
      <always_on>true</always_on>
      <visualize>true</visualize>
      <update_rate>15.0</update_rate>
      <camera>
        <horizontal_fov>1.047197</horizontal_fov>
        <image>
          <format>B8G8R8</format>
          <width>640</width>
          <height>480</height>
        </image>
        <depth_camera>
        </depth_camera>
        <clip>
          <near>0.05</near>
          <far>50</far>
        </clip>
      </camera>
      <plugin filename="libgazebo_ros_openni_kinect.so" name="camera_controller">
        <baseline>0.1</baseline>
        <alwaysOn>true</alwaysOn>
        <updateRate>10.0</updateRate>
        <cameraName>kinect</cameraName>
        <frameName>camera_link_optical</frameName>
        <imageTopicName>rgb/image_raw</imageTopicName>
        <depthImageTopicName>depth/image_raw</depthImageTopicName>
        <pointCloudTopicName>depth/points</pointCloudTopicName>
        <cameraInfoTopicName>rgb/camera_info</cameraInfoTopicName>
        <depthImageCameraInfoTopicName>depth/camera_info</depthImageCameraInfoTopicName>
        <pointCloudCutoff>0.4</pointCloudCutoff>
        <hackBaseline>0.07</hackBaseline>
        <distortionK1>0.0</distortionK1>
        <distortionK2>0.0</distortionK2>
        <distortionK3>0.0</distortionK3>
        <distortionT1>0.0</distortionT1>
        <distortionT2>0.0</distortionT2>
        <CxPrime>0.0</CxPrime>
        <Cx>0.0</Cx>
        <Cy>0.0</Cy>
        <focalLength>0.0</focalLength>
      </plugin>
    </sensor>
  </gazebo>
  <!-- IMU sensor -->
  <gazebo reference="imu_link">
    <gravity>true</gravity>
    <sensor name="imu_sensor" type="imu">
      <always_on>true</always_on>
      <update_rate>100</update_rate>
      <visualize>true</visualize>
      <topic>__default_topic__</topic>
      <plugin filename="libgazebo_ros_imu_sensor.so" name="imu_plugin">
        <topicName>imu</topicName>
        <bodyName>imu_link</bodyName>
        <updateRateHZ>10.0</updateRateHZ>
        <gaussianNoise>0.0</gaussianNoise>
        <xyzOffset>0 0 0</xyzOffset>
        <rpyOffset>0 0 0</rpyOffset>
        <frameName>imu_link</frameName>
      </plugin>
      <pose>0 0 0 0 0 0</pose>
    </sensor>
  </gazebo>
  <!-- Ultrasonic sensors -->
  <gazebo reference="us_1_link">
    <sensor name="range" type="ray">
      <ray>
        <scan>
          <horizontal>
            <samples>1</samples>
            <resolution>1.0</resolution>
            <min_angle>-0.01</min_angle>
            <max_angle>0.01</max_angle>
          </horizontal>
          <vertical>
            <samples>1</samples>
            <resolution>1</resolution>
            <min_angle>-0.01</min_angle>
            <max_angle>0.01</max_angle>
          </vertical>
        </scan>
        <range>
          <min>0.01</min>
          <max>3.75</max>
          <resolution>0.02</resolution>
        </range>
      </ray>
      <plugin filename="libgazebo_ros_range.so" name="gazebo_ros_range">
        <gaussianNoise>0.005</gaussianNoise>
        <alwaysOn>true</alwaysOn>
        <updateRate>50</updateRate>
        <topicName>ultrasonic/us1</topicName>
        <frameName>us_1_link</frameName>
        <radiation>INFRARED</radiation>
        <fov>0.2967</fov>
      </plugin>
    </sensor>
  </gazebo>
  <gazebo>
    <plugin filename="libgazebo_ros_control.so" name="ros_control">
      <legacyModeNS>false</legacyModeNS>
      <robotSimType>gazebo_ros_control/DefaultRobotHWSim</robotSimType>
    </plugin>
  </gazebo>
  <gazebo>
    <plugin filename="libgazebo_ros_planar_move.so" name="mpo_500_controller">
      <commandTopic>cmd_vel</commandTopic>
      <odometryTopic>odom</odometryTopic>
      <odometryFrame>odom</odometryFrame>
      <odometryRate>100.0</odometryRate>
      <robotBaseFrame>base_link</robotBaseFrame>
    </plugin>
  </gazebo>
  <!-- Microscan - Comment/Uncomment if required -->
  <!-- <xacro:include filename="$(find neo_mpo_500)/robot_model/urdf/mpo_500_xacros/micro_scan.xacro" />-->
  <!-- USS and IMU - Comment/Uncomment if required  -->
  <!--<xacro:include filename="$(find neo_mpo_500)/robot_model/urdf/mpo_500_xacros/imu.xacro" />

    <xacro:include filename="$(find neo_mpo_500)/robot_model/mmo_500/urdf/mpo_500_xacros/ultrasonic.xacro" /> -->
  <gazebo>
    <plugin filename="libgazebo_ros_control.so" name="ros_control">
      <robotNamespace>/mpo_500</robotNamespace>
      <robotSimType>gazebo_ros_control/DefaultRobotHWSim</robotSimType>
      <legacyModeNS>true</legacyModeNS>
    </plugin>
  </gazebo>
  <!--
    <plugin name="gazebo_ros_power_monitor_controller" filename="libgazebo_ros_power_monitor.so">
      <alwaysOn>true</alwaysOn>
      <updateRate>1.0</updateRate>
      <timeout>5</timeout>
      <powerStateTopic>power_state</powerStateTopic>
      <powerStateRate>10.0</powerStateRate>
      <fullChargeCapacity>87.78</fullChargeCapacity>     
      <dischargeRate>-474</dischargeRate>
      <chargeRate>525</chargeRate>
      <dischargeVoltage>15.52</dischargeVoltage>
      <chargeVoltage>16.41</chargeVoltage>
    </plugin>
-->
  <!-- Base Macro-->
  <link name="base_link"/>
  <joint name="base_footprint_joint" type="fixed">
    <origin rpy="0 0 0" xyz="0 0 0"/>
    <axis xyz="0 0 -1"/>
    <joint_properties damping="1" friction="1"/>
    <parent link="base_link"/>
    <child link="base_footprint"/>
  </joint>
  <!-- Link -->
  <link name="base_footprint">
    <inertial>
      <mass value="80"/>
      <origin xyz="0 0 0"/>
      <inertia ixx="3.253" ixy="0.0" ixz="0.0" iyy="3.253" iyz="0.0" izz="3.253"/>
    </inertial>
    <visual>
      <origin rpy="-1.571 0 1.571" xyz="0. 0. 0"/>
      <geometry>
        <mesh filename="package://neo_simulation/robots/mpo_500/meshes/MPO_500/MPO-500-BODY.dae" scale="0.001 0.001 0.001"/>
      </geometry>
    </visual>
    <collision>
      <origin rpy="-1.571 0 1.571" xyz="0. 0. 0.0"/>
      <geometry>
        <!--<box size="0.68 0.41 0.25"/> -->
        <mesh filename="package://neo_simulation/robots/mpo_500/meshes/MPO_500/MPO-500-BODY.dae" scale="0.001 0.001 0.001"/>
      </geometry>
    </collision>
  </link>
  <joint name="mpo_500_omni_wheel_front_left_joint" type="revolute">
    <origin rpy="0 0 0" xyz="0.25 0.28 0.13"/>
    <axis xyz="0 1 0"/>
    <joint_properties damping="100" friction="1000"/>
    <limit effort="1000.0" lower="-1e+16" upper="1e+16" velocity="3.5"/>
    <joint_properties damping="1.0" friction="1"/>
    <parent link="base_footprint"/>
    <child link="mpo_500_omni_wheel_front_left_link"/>
  </joint>
  <link name="mpo_500_omni_wheel_front_left_link" type="wheel">
    <inertial>
      <mass value="1"/>
      <origin rpy="0 0 0" xyz="0 0 0"/>
      <inertia ixx="0.00044332" ixy="0" ixz="0" iyy="0.00044332" iyz="0" izz="0.00072"/>
    </inertial>
    <visual>
      <origin rpy="0 0 0" xyz="0 0 0"/>
      <geometry>
        <mesh filename="package://neo_simulation/robots/mpo_500/meshes/MPO_500/MPO-500-WHEEL.dae" scale="0.001 0.001 0.001"/>
      </geometry>
    </visual>
    <collision>
      <origin rpy="0 0 0" xyz="0 0 0"/>
      <geometry>
        <mesh filename="package://neo_simulation/robots/mpo_500/meshes/MPO_500/MPO-500-WHEEL.dae" scale="0.001 0.001 0.001"/>
      </geometry>
    </collision>
  </link>
  <joint name="mpo_500_omni_wheel_front_right_joint" type="revolute">
    <origin rpy="0 0 3.14" xyz="0.25 -0.28 0.13"/>
    <axis xyz="0 1 0"/>
    <joint_properties damping="100" friction="1000"/>
    <limit effort="1000.0" lower="-1e+16" upper="1e+16" velocity="3.5"/>
    <joint_properties damping="1.0" friction="1"/>
    <parent link="base_footprint"/>
    <child link="mpo_500_omni_wheel_front_right_link"/>
  </joint>
  <link name="mpo_500_omni_wheel_front_right_link" type="wheel">
    <inertial>
      <mass value="1"/>
      <origin rpy="0 0 0" xyz="0 0 0"/>
      <inertia ixx="0.00044332" ixy="0" ixz="0" iyy="0.00044332" iyz="0" izz="0.00072"/>
    </inertial>
    <visual>
      <origin rpy="0 0 0" xyz="0 0 0"/>
      <geometry>
        <mesh filename="package://neo_simulation/robots/mpo_500/meshes/MPO_500/MPO-500-WHEEL.dae" scale="0.001 0.001 0.001"/>
      </geometry>
    </visual>
    <collision>
      <origin rpy="0 0 0" xyz="0 0 0"/>
      <geometry>
        <mesh filename="package://neo_simulation/robots/mpo_500/meshes/MPO_500/MPO-500-WHEEL.dae" scale="0.001 0.001 0.001"/>
      </geometry>
    </collision>
  </link>
  <joint name="mpo_500_omni_wheel_back_left_joint" type="revolute">
    <origin rpy="0 0 0" xyz="-0.25 0.28 0.13"/>
    <axis xyz="0 1 0"/>
    <joint_properties damping="100" friction="1000"/>
    <limit effort="1000.0" lower="-1e+16" upper="1e+16" velocity="3.5"/>
    <joint_properties damping="1.0" friction="1"/>
    <parent link="base_footprint"/>
    <child link="mpo_500_omni_wheel_back_left_link"/>
  </joint>
  <link name="mpo_500_omni_wheel_back_left_link" type="wheel">
    <inertial>
      <mass value="1"/>
      <origin rpy="0 0 0" xyz="0 0 0"/>
      <inertia ixx="0.00044332" ixy="0" ixz="0" iyy="0.00044332" iyz="0" izz="0.00072"/>
    </inertial>
    <visual>
      <origin rpy="0 0 0" xyz="0 0 0"/>
      <geometry>
        <mesh filename="package://neo_simulation/robots/mpo_500/meshes/MPO_500/MPO-500-WHEEL.dae" scale="0.001 0.001 0.001"/>
      </geometry>
    </visual>
    <collision>
      <origin rpy="0 0 0" xyz="0 0 0"/>
      <geometry>
        <mesh filename="package://neo_simulation/robots/mpo_500/meshes/MPO_500/MPO-500-WHEEL.dae" scale="0.001 0.001 0.001"/>
      </geometry>
    </collision>
  </link>
  <joint name="mpo_500_omni_wheel_back_right_joint" type="revolute">
    <origin rpy="0 0 3.14" xyz="-0.25 -0.28 0.13"/>
    <axis xyz="0 1 0"/>
    <joint_properties damping="100" friction="1000"/>
    <limit effort="1000.0" lower="-1e+16" upper="1e+16" velocity="3.5"/>
    <joint_properties damping="1.0" friction="1"/>
    <parent link="base_footprint"/>
    <child link="mpo_500_omni_wheel_back_right_link"/>
  </joint>
  <link name="mpo_500_omni_wheel_back_right_link" type="wheel">
    <inertial>
      <mass value="1"/>
      <origin rpy="0 0 0" xyz="0 0 0"/>
      <inertia ixx="0.00044332" ixy="0" ixz="0" iyy="0.00044332" iyz="0" izz="0.00072"/>
    </inertial>
    <visual>
      <origin rpy="0 0 0" xyz="0 0 0"/>
      <geometry>
        <mesh filename="package://neo_simulation/robots/mpo_500/meshes/MPO_500/MPO-500-WHEEL.dae" scale="0.001 0.001 0.001"/>
      </geometry>
    </visual>
    <collision>
      <origin rpy="0 0 0" xyz="0 0 0"/>
      <geometry>
        <mesh filename="package://neo_simulation/robots/mpo_500/meshes/MPO_500/MPO-500-WHEEL.dae" scale="0.001 0.001 0.001"/>
      </geometry>
    </collision>
  </link>
  <joint name="lidar_1_joint" type="fixed">
    <axis xyz="0 1 0"/>
    <origin rpy="0 0 0" xyz="0.442 0 0.372"/>
    <parent link="base_link"/>
    <child link="lidar_1_link"/>
  </joint>
  <link name="lidar_1_link" type="laser">
    <inertial>
      <mass value="0.001"/>
      <origin rpy="0 0 0" xyz="0 0 0"/>
      <inertia ixx="0.0001" ixy="0" ixz="0" iyy="0.000001" iyz="0" izz="0.0001"/>
    </inertial>
    <visual>
      <origin rpy="-1.57 0 3.14" xyz="0 0 -0.12"/>
      <geometry>
        <mesh filename="package://neo_simulation/robots/mpo_500/meshes/MPO_500/SICK-S300.dae" scale="0.001 0.001 0.001"/>
      </geometry>
    </visual>
    <collision>
      <origin rpy="-1.57 0 3.14" xyz="0 0 -0.12"/>
      <geometry>
        <mesh filename="package://neo_simulation/robots/mpo_500/meshes/MPO_500/SICK-S300.dae" scale="0.001 0.001 0.001"/>
      </geometry>
    </collision>
  </link>
  <joint name="lidar_2_joint" type="fixed">
    <axis xyz="0 1 0"/>
    <origin rpy="0 0 3.14" xyz="-0.442 0 0.372"/>
    <parent link="base_link"/>
    <child link="lidar_2_link"/>
  </joint>
  <link name="lidar_2_link" type="laser">
    <inertial>
      <mass value="0.001"/>
      <origin rpy="0 0 0" xyz="0 0 0"/>
      <inertia ixx="0.0001" ixy="0" ixz="0" iyy="0.000001" iyz="0" izz="0.0001"/>
    </inertial>
    <visual>
      <origin rpy="-1.57 0 3.14" xyz="0 0 -0.12"/>
      <geometry>
        <mesh filename="package://neo_simulation/robots/mpo_500/meshes/MPO_500/SICK-S300.dae" scale="0.001 0.001 0.001"/>
      </geometry>
    </visual>
    <collision>
      <origin rpy="-1.57 0 3.14" xyz="0 0 -0.12"/>
      <geometry>
        <mesh filename="package://neo_simulation/robots/mpo_500/meshes/MPO_500/SICK-S300.dae" scale="0.001 0.001 0.001"/>
      </geometry>
    </collision>
  </link>
  <!--+++++++++++++++++++ IMU ++++++++++++++++++++++++-->
  <!-- Comment or uncomment based on your requirement -->
  <!--   <xacro:imu name="imu_1" parent="base_link">
    <origin xyz="0.100 0 0.300" rpy="0 0 3.14" />
  </xacro:imu> -->
  <!--+++++++++++++++++++ Ultra Sonic ++++++++++++++++++++++++-->
  <!-- Comment or uncomment based on your requirement -->
  <!-- SENSOR 1 -->
  <!-- xacro:us_sensor name="us_1" parent="base_link">
    <origin xyz="0.100 0 0.300" rpy="0 3.14 3.14" />
  </xacro:us_sensor-->
  <!-- SENSOR 2 -->
  <!-- xacro:us_sensor name="us_2" parent="base_link">
    <origin xyz="0.110 0 0.300" rpy="0 3.14 3.14" />
  </xacro:us_sensor-->
  <!-- SENSOR 3 -->
  <!-- xacro:us_sensor name="us_3" parent="base_link">
    <origin xyz="0.120 0 0.300" rpy="0 3.14 3.14" />
  </xacro:us_sensor-->
  <!-- SENSOR 4 -->
  <!-- xacro:us_sensor name="us_4" parent="base_link">
    <origin xyz="0.130 0 0.300" rpy="0 3.14 3.14" />
  </xacro:us_sensor-->
  <!-- SENSOR 5 -->
  <!-- xacro:us_sensor name="us_5" parent="base_link">
    <origin xyz="0.140 0 0.300" rpy="0 3.14 3.14" />
  </xacro:us_sensor-->
  <!-- SENSOR 6 -->
  <!-- xacro:us_sensor name="us_6" parent="base_link">
    <origin xyz="0.150 0 0.300" rpy="0 3.14 3.14" />
  </xacro:us_sensor-->
  <!-- SENSOR 7 -->
  <!-- xacro:us_sensor name="us_7" parent="base_link">
    <origin xyz="0.160 0 0.300" rpy="0 3.14 3.14" />
  </xacro:us_sensor-->
  <!-- SENSOR 8 -->
  <!-- xacro:us_sensor name="us_8" parent="base_link">
    <origin xyz="0.170 0 0.300" rpy="0 3.14 3.14" />
  </xacro:us_sensor-->
  <!-- SENSOR 9 -->
  <!-- xacro:us_sensor name="us_9" parent="base_link">
    <origin xyz="0.180 0 0.300" rpy="0 3.14 3.14" />
  </xacro:us_sensor-->
  <!-- SENSOR 10 -->
  <!-- xacro:us_sensor name="us_10" parent="base_link">
    <origin xyz="0.100 0 0.300" rpy="0 3.14 3.14" />
  </xacro:us_sensor-->
  <!-- SENSOR 11 -->
  <!-- xacro:us_sensor name="us_11" parent="base_link">
    <origin xyz="0.100 0 0.300" rpy="0 3.14 3.14" />
  </xacro:us_sensor-->
  <!-- SENSOR 12 -->
  <!-- xacro:us_sensor name="us_12" parent="base_link">
    <origin xyz="0.190 0 0.300" rpy="0 3.14 3.14" />
  </xacro:us_sensor-->
  <!-- SENSOR 13 -->
  <!-- xacro:us_sensor name="us_13" parent="base_link">
    <origin xyz="0.200 0 0.300" rpy="0 3.14 3.14" />
  </xacro:us_sensor-->
  <!-- SENSOR 14 -->
  <!-- xacro:us_sensor name="us_14" parent="base_link">
    <origin xyz="0.210 0 0.300" rpy="0 3.14 3.14" />
  </xacro:us_sensor-->
  <!-- SENSOR 15 -->
  <!-- xacro:us_sensor name="us_15" parent="base_link">
    <origin xyz="0.220 0 0.300" rpy="0 3.14 3.14" />
  </xacro:us_sensor-->
  <!-- SENSOR 16 -->
  <!-- xacro:us_sensor name="us_16" parent="base_link">
    <origin xyz="0.230 0 0.300" rpy="0 3.14 3.14" />
  </xacro:us_sensor-->
  <link name="kinect_link">
    <visual>
      <origin rpy="0 0 0" xyz="0 0 0"/>
      <geometry>
        <mesh filename="package://neo_simulation/robots/mpo_500/meshes/MPO_500/kinect.stl"/>
      </geometry>
      <material name="light_grey">
        <color rgba="0.7 0.7 0.7 1.0"/>
      </material>
    </visual>
    <collision>
      <origin rpy="0 0 0" xyz="0 0 0"/>
      <geometry>
        <mesh filename="package://neo_simulation/robots/mpo_500/meshes/MPO_500/kinect.stl"/>
      </geometry>
    </collision>
  </link>
  <link name="camera_link_optical">
   </link>
  <joint name="kinect_joint" type="fixed">
    <!--<limit lower= "-3.0" upper= "3.0" effort="1" velocity="2" />
      <axis xyz="0 0 1" />-->
    <parent link="base_link"/>
    <child link="kinect_link"/>
    <origin rpy="0 0.4 0" xyz="0.04 0 1.444"/>
  </joint>
  <joint name="camera_optical_joint" type="fixed">
    <origin rpy="-1.5708 0 -1.5708" xyz="0 0 0"/>
    <parent link="kinect_link"/>
    <child link="camera_link_optical"/>
  </joint>
  <gazebo reference="kinect_link">
    <material>Gazebo/Grey</material>
    <turnGravityOff>false</turnGravityOff>
  </gazebo>
  <!--cabinet-->
  <!--  <xacro:mmo_500_cabinet name="cabinet" parent="base_link">
  	<origin xyz="0.072 0 0.386" rpy="0 0 0" />
  </xacro:mmo_500_cabinet>-->
  <joint name="torso_joint" type="fixed">
    <origin rpy="0 0 0" xyz="0 0 0.886"/>
    <joint_properties damping="1" friction="1"/>
    <parent link="base_link"/>
    <child link="torso_link"/>
  </joint>
  <link name="torso_link">
    <inertial>
      <mass value="2"/>
      <origin rpy="0 0 0" xyz="0 0 0"/>
      <inertia ixx="0.00" ixy="0.0" ixz="0.0" iyx="0.0" iyy="0.00" iyz="0.0" izx="0.0" izy="0.0" izz="0.00"/>
    </inertial>
    <visual>
      <origin rpy="0 0 -1.5708" xyz="0 0 0"/>
      <geometry>
        <box size="0.2 0.1 1"/>
      </geometry>
      <material name="LightGrey">
        <color rgba="0.7 0.7 0.7 1.0"/>
      </material>
    </visual>
    <collision>
      <origin rpy="0 0 -1.5708" xyz="0 0 0"/>
      <geometry>
        <box size="0.2 0.1 1"/>
      </geometry>
    </collision>
  </link>
  <gazebo reference="torso_link">
    <material>Gazebo/Grey</material>
    <turnGravityOff>false</turnGravityOff>
  </gazebo>
  <joint name="shoulder_joint" type="fixed">
    <origin rpy="0 0 0" xyz="0 0 0.505"/>
    <joint_properties damping="1" friction="1"/>
    <parent link="torso_link"/>
    <child link="shoulder_link"/>
  </joint>
  <link name="shoulder_link">
    <inertial>
      <mass value="2"/>
      <origin rpy="0 0 0" xyz="0 0 0"/>
      <inertia ixx="0" ixy="0.0" ixz="0.0" iyx="0.0" iyy="0.0" iyz="0.0" izx="0.0" izy="0.0" izz="0.0"/>
    </inertial>
    <visual>
      <origin rpy="0 0 -1.5708" xyz="0 0 0"/>
      <geometry>
        <box size="0.7 0.15 0.01"/>
      </geometry>
      <material name="LightGrey">
        <color rgba="0.7 0.7 0.7 1.0"/>
      </material>
    </visual>
    <collision>
      <origin rpy="0 0 -1.5708" xyz="0. 0. 0"/>
      <geometry>
        <box size="0.7 0.15 0.01"/>
      </geometry>
    </collision>
  </link>
  <gazebo reference="shoulder_link">
    <material>Gazebo/Grey</material>
    <turnGravityOff>false</turnGravityOff>
  </gazebo>
  <!--ur10-->
  <!--<xacro:ur10_robot parent="cabinet_link" prefix="ur10" joint_limited="true"
		 shoulder_pan_lower_limit="${-pi}" shoulder_pan_upper_limit="${pi}"
		 shoulder_lift_lower_limit="${-pi}" shoulder_lift_upper_limit="${pi}"
		 elbow_joint_lower_limit="${-pi}" elbow_joint_upper_limit="${pi}"
		 wrist_1_lower_limit="${-pi}" wrist_1_upper_limit="${pi}"
		 wrist_2_lower_limit="${-pi}" wrist_2_upper_limit="${pi}"
		 wrist_3_lower_limit="${-pi}" wrist_3_upper_limit="${pi}">
  </xacro:ur10_robot> -->
  <!-- measured from model -->
  <!--property name="shoulder_height" value="0.089159" /-->
  <!--property name="shoulder_offset" value="0.13585" /-->
  <!-- shoulder_offset - elbow_offset + wrist_1_length = 0.10915 -->
  <!--property name="upper_arm_length" value="0.42500" /-->
  <!--property name="elbow_offset" value="0.1197" /-->
  <!-- CAD measured -->
  <!--property name="forearm_length" value="0.39225" /-->
  <!--property name="wrist_1_length" value="0.093" /-->
  <!-- CAD measured -->
  <!--property name="wrist_2_length" value="0.09465" /-->
  <!-- In CAD this distance is 0.930, but in the spec it is 0.09465 -->
  <!--property name="wrist_3_length" value="0.0823" /-->
  <!-- manually measured -->
  <joint name="ur5_left_joint" type="fixed">
    <parent link="shoulder_link"/>
    <child link="ur5_left_base_link"/>
    <!--<origin xyz="0.0 0.28 -0.005" rpy="0 -3.14159 0" />-->
    <origin rpy="0 -3.14159 0" xyz="0.0 0.28 -0.005"/>
  </joint>
  <link name="ur5_left_base_link">
    <visual>
      <geometry>
        <mesh filename="package://neo_simulation/robots/mpo_500/meshes/ur5/visual/base.dae"/>
      </geometry>
      <material name="LightGrey">
        <color rgba="0.7 0.7 0.7 1.0"/>
      </material>
    </visual>
    <collision>
      <geometry>
        <mesh filename="package://neo_simulation/robots/mpo_500/meshes/ur5/collision/base.stl"/>
      </geometry>
    </collision>
    <inertial>
      <mass value="4.0"/>
      <origin rpy="0 0 0" xyz="0.0 0.0 0.0"/>
      <inertia ixx="0.00443333156" ixy="0.0" ixz="0.0" iyy="0.00443333156" iyz="0.0" izz="0.0072"/>
    </inertial>
  </link>
  <joint name="ur5_left_shoulder_pan_joint" type="revolute">
    <parent link="ur5_left_base_link"/>
    <child link="ur5_left_shoulder_link"/>
    <origin rpy="0.0 0.0 0.0" xyz="0.0 0.0 0.089159"/>
    <axis xyz="0 0 1"/>
    <limit effort="150.0" lower="-3.14159265359" upper="3.14159265359" velocity="3.15"/>
    <dynamics damping="0.0" friction="0.0"/>
  </joint>
  <link name="ur5_left_shoulder_link">
    <visual>
      <geometry>
        <mesh filename="package://neo_simulation/robots/mpo_500/meshes/ur5/visual/shoulder.dae"/>
      </geometry>
      <material name="LightGrey">
        <color rgba="0.7 0.7 0.7 1.0"/>
      </material>
    </visual>
    <collision>
      <geometry>
        <mesh filename="package://neo_simulation/robots/mpo_500/meshes/ur5/collision/shoulder.stl"/>
      </geometry>
    </collision>
    <inertial>
      <mass value="3.7"/>
      <origin rpy="0 0 0" xyz="0.0 0.0 0.0"/>
      <inertia ixx="0.010267495893" ixy="0.0" ixz="0.0" iyy="0.010267495893" iyz="0.0" izz="0.00666"/>
    </inertial>
  </link>
  <joint name="ur5_left_shoulder_lift_joint" type="revolute">
    <parent link="ur5_left_shoulder_link"/>
    <child link="ur5_left_upper_arm_link"/>
    <origin rpy="0.0 0 0.0" xyz="0.0 0.13585 0.0"/>
    <axis xyz="0 1 0"/>
    <limit effort="150.0" lower="-3.14159265359" upper="3.14159265359" velocity="3.15"/>
    <dynamics damping="0.0" friction="0.0"/>
  </joint>
  <link name="ur5_left_upper_arm_link">
    <visual>
      <geometry>
        <mesh filename="package://neo_simulation/robots/mpo_500/meshes/ur5/visual/upperarm.dae"/>
      </geometry>
      <material name="LightGrey">
        <color rgba="0.7 0.7 0.7 1.0"/>
      </material>
    </visual>
    <collision>
      <geometry>
        <mesh filename="package://neo_simulation/robots/mpo_500/meshes/ur5/collision/upperarm.stl"/>
      </geometry>
    </collision>
    <inertial>
      <mass value="8.393"/>
      <origin rpy="0 0 0" xyz="0.0 0.0 0.28"/>
      <inertia ixx="0.22689067591" ixy="0.0" ixz="0.0" iyy="0.22689067591" iyz="0.0" izz="0.0151074"/>
    </inertial>
  </link>
  <joint name="ur5_left_elbow_joint" type="revolute">
    <parent link="ur5_left_upper_arm_link"/>
    <child link="ur5_left_forearm_link"/>
    <origin rpy="0.0 0.0 0.0" xyz="0.0 -0.1197 0.425"/>
    <!--1.25-->
    <axis xyz="0 1 0"/>
    <limit effort="150.0" lower="-3.14159265359" upper="0" velocity="3.15"/>
    <dynamics damping="0.0" friction="0.0"/>
  </joint>
  <link name="ur5_left_forearm_link">
    <visual>
      <geometry>
        <mesh filename="package://neo_simulation/robots/mpo_500/meshes/ur5/visual/forearm.dae"/>
      </geometry>
      <material name="LightGrey">
        <color rgba="0.7 0.7 0.7 1.0"/>
      </material>
    </visual>
    <collision>
      <geometry>
        <mesh filename="package://neo_simulation/robots/mpo_500/meshes/ur5/collision/forearm.stl"/>
      </geometry>
    </collision>
    <inertial>
      <mass value="2.275"/>
      <origin rpy="0 0 0" xyz="0.0 0.0 0.196125"/>
      <inertia ixx="0.0312167910289" ixy="0.0" ixz="0.0" iyy="0.0312167910289" iyz="0.0" izz="0.004095"/>
    </inertial>
  </link>
  <joint name="ur5_left_wrist_1_joint" type="revolute">
    <parent link="ur5_left_forearm_link"/>
    <child link="ur5_left_wrist_1_link"/>
    <origin rpy="0.0 0.0 0.0" xyz="0.0 0.0 0.39225"/>
    <axis xyz="0 1 0"/>
    <limit effort="28.0" lower="-3.14159265359" upper="3.14159265359" velocity="3.2"/>
    <dynamics damping="0.0" friction="0.0"/>
  </joint>
  <link name="ur5_left_wrist_1_link">
    <visual>
      <geometry>
        <mesh filename="package://neo_simulation/robots/mpo_500/meshes/ur5/visual/wrist1.dae"/>
      </geometry>
      <material name="LightGrey">
        <color rgba="0.7 0.7 0.7 1.0"/>
      </material>
    </visual>
    <collision>
      <geometry>
        <mesh filename="package://neo_simulation/robots/mpo_500/meshes/ur5/collision/wrist1.stl"/>
      </geometry>
    </collision>
    <inertial>
      <mass value="1.219"/>
      <origin rpy="0 0 0" xyz="0.0 0.093 0.0"/>
      <inertia ixx="0.00255989897604" ixy="0.0" ixz="0.0" iyy="0.00255989897604" iyz="0.0" izz="0.0021942"/>
    </inertial>
  </link>
  <joint name="ur5_left_wrist_2_joint" type="revolute">
    <parent link="ur5_left_wrist_1_link"/>
    <child link="ur5_left_wrist_2_link"/>
    <origin rpy="0.0 0.0 1.5708" xyz="0.0 0.093 0.0"/>
    <axis xyz="0 0 1"/>
    <limit effort="28.0" lower="-3.14159265359" upper="3.14159265359" velocity="3.2"/>
    <dynamics damping="0.0" friction="0.0"/>
  </joint>
  <link name="ur5_left_wrist_2_link">
    <visual>
      <geometry>
        <mesh filename="package://neo_simulation/robots/mpo_500/meshes/ur5/visual/wrist2.dae"/>
      </geometry>
      <material name="LightGrey">
        <color rgba="0.7 0.7 0.7 1.0"/>
      </material>
    </visual>
    <collision>
      <geometry>
        <mesh filename="package://neo_simulation/robots/mpo_500/meshes/ur5/collision/wrist2.stl"/>
      </geometry>
    </collision>
    <inertial>
      <mass value="1.219"/>
      <origin rpy="0 0 0" xyz="0.0 0.0 0.09465"/>
      <inertia ixx="0.00255989897604" ixy="0.0" ixz="0.0" iyy="0.00255989897604" iyz="0.0" izz="0.0021942"/>
    </inertial>
  </link>
  <joint name="ur5_left_wrist_3_joint" type="revolute">
    <parent link="ur5_left_wrist_2_link"/>
    <child link="ur5_left_wrist_3_link"/>
    <origin rpy="0.0 0.0 0.0" xyz="0.0 0.0 0.09465"/>
    <axis xyz="0 1 0"/>
    <limit effort="28.0" lower="-3.14159265359" upper="3.14159265359" velocity="3.2"/>
    <dynamics damping="0.0" friction="0.0"/>
  </joint>
  <link name="ur5_left_wrist_3_link">
    <visual>
      <geometry>
        <mesh filename="package://neo_simulation/robots/mpo_500/meshes/ur5/visual/wrist3.dae"/>
      </geometry>
      <material name="LightGrey">
        <color rgba="0.7 0.7 0.7 1.0"/>
      </material>
    </visual>
    <collision>
      <geometry>
        <mesh filename="package://neo_simulation/robots/mpo_500/meshes/ur5/collision/wrist3.stl"/>
      </geometry>
    </collision>
    <inertial>
      <mass value="0.1879"/>
      <origin rpy="1.57079632679 0 0" xyz="0.0 0.06505 0.0"/>
      <inertia ixx="8.46958911216e-05" ixy="0.0" ixz="0.0" iyy="8.46958911216e-05" iyz="0.0" izz="0.0001321171875"/>
    </inertial>
  </link>
  <joint name="ur5_left_ee_fixed_joint" type="fixed">
    <parent link="ur5_left_wrist_3_link"/>
    <child link="ur5_left_ee_link"/>
    <origin rpy="0.0 0.0 1.57079632679" xyz="0.0 0.0823 0.0"/>
  </joint>
  <link name="ur5_left_ee_link">
    <collision>
      <geometry>
        <box size="0.01 0.01 0.01"/>
      </geometry>
      <origin rpy="0 0 0" xyz="-0.01 0 0"/>
    </collision>
  </link>
  <transmission name="ur5_left_shoulder_pan_trans">
    <type>transmission_interface/SimpleTransmission</type>
    <joint name="ur5_left_shoulder_pan_joint">
      <hardwareInterface>hardware_interface/PositionJointInterface</hardwareInterface>
    </joint>
    <actuator name="ur5_left_shoulder_pan_motor">
      <mechanicalReduction>1</mechanicalReduction>
    </actuator>
  </transmission>
  <transmission name="ur5_left_shoulder_lift_trans">
    <type>transmission_interface/SimpleTransmission</type>
    <joint name="ur5_left_shoulder_lift_joint">
      <hardwareInterface>hardware_interface/PositionJointInterface</hardwareInterface>
    </joint>
    <actuator name="ur5_left_shoulder_lift_motor">
      <mechanicalReduction>1</mechanicalReduction>
    </actuator>
  </transmission>
  <transmission name="ur5_left_elbow_trans">
    <type>transmission_interface/SimpleTransmission</type>
    <joint name="ur5_left_elbow_joint">
      <hardwareInterface>hardware_interface/PositionJointInterface</hardwareInterface>
    </joint>
    <actuator name="ur5_left_elbow_motor">
      <mechanicalReduction>1</mechanicalReduction>
    </actuator>
  </transmission>
  <transmission name="ur5_left_wrist_1_trans">
    <type>transmission_interface/SimpleTransmission</type>
    <joint name="ur5_left_wrist_1_joint">
      <hardwareInterface>hardware_interface/PositionJointInterface</hardwareInterface>
    </joint>
    <actuator name="ur5_left_wrist_1_motor">
      <mechanicalReduction>1</mechanicalReduction>
    </actuator>
  </transmission>
  <transmission name="ur5_left_wrist_2_trans">
    <type>transmission_interface/SimpleTransmission</type>
    <joint name="ur5_left_wrist_2_joint">
      <hardwareInterface>hardware_interface/PositionJointInterface</hardwareInterface>
    </joint>
    <actuator name="ur5_left_wrist_2_motor">
      <mechanicalReduction>1</mechanicalReduction>
    </actuator>
  </transmission>
  <transmission name="ur5_left_wrist_3_trans">
    <type>transmission_interface/SimpleTransmission</type>
    <joint name="ur5_left_wrist_3_joint">
      <hardwareInterface>hardware_interface/PositionJointInterface</hardwareInterface>
    </joint>
    <actuator name="ur5_left_wrist_3_motor">
      <mechanicalReduction>1</mechanicalReduction>
    </actuator>
  </transmission>
  <gazebo reference="ur5_left_shoulder_link">
    <selfCollide>true</selfCollide>
  </gazebo>
  <gazebo reference="ur5_left_upper_arm_link">
    <selfCollide>true</selfCollide>
  </gazebo>
  <gazebo reference="ur5_left_forearm_link">
    <selfCollide>true</selfCollide>
  </gazebo>
  <gazebo reference="ur5_left_wrist_1_link">
    <selfCollide>true</selfCollide>
  </gazebo>
  <gazebo reference="ur5_left_wrist_3_link">
    <selfCollide>true</selfCollide>
  </gazebo>
  <gazebo reference="ur5_left_wrist_2_link">
    <selfCollide>true</selfCollide>
  </gazebo>
  <gazebo reference="ur5_left_ee_link">
    <selfCollide>true</selfCollide>
  </gazebo>
  <!-- ROS base_link to UR 'Base' Coordinates transform -->
  <!-- NOTE: this rotation is only needed as long as base_link itself is
                 not corrected wrt the real robot (ie: rotated over 180
                 degrees)
      -->
  <!-- <link name="${prefix}base"/>
    <joint name="${prefix}base_link-base_fixed_joint" type="fixed">
     
      <origin xyz="0 0 0" rpy="0 0 ${-pi}"/>
      <parent link="${prefix}base_link"/>
      <child link="${prefix}base"/>
    </joint>-->
  <!-- Frame coincident with all-zeros TCP on UR controller -->
  <link name="ur5_left_tool0"/>
  <joint name="ur5_left_wrist_3_link-tool0_fixed_joint" type="fixed">
    <origin rpy="-3.14159265359 0 1.57079632679" xyz="0 0.2683 0"/>
    <parent link="ur5_left_wrist_3_link"/>
    <child link="ur5_left_tool0"/>
  </joint>
  <!--<link name="${prefix}tool_link"0.3183 0.2683 0.2483/>
    <joint name="${prefix}tool_joint" type="fixed">
      <parent link="${prefix}tool0"/>
      <child link="${prefix}tool_link"/>
      <origin xyz="0 0 0.18" rpy="3.14159 -1.5708 0"/>   
    </joint>-->
  <!--<link name="${prefix}gripper_link">
      <visual>
        <geometry>
          <cylinder radius="0.025" length="0.040" />
        </geometry>
        <material name="LightGrey">
          <color rgba="0.7 0.7 0.7 1.0"/>
        </material>
      </visual>
      <collision>
        <geometry>
           <cylinder radius="0.025" length="0.040" />
        </geometry>
      </collision>
      <inertial>
        <origin xyz="0 0 0" rpy="0 0 0" />
        <mass value= "0.1"/>
        <inertia ixx=" 2.89583333333e-05" ixy="0" ixz="0" iyx="0" iyy="2.89583333333e-05" iyz="0" izx="0" izy="0" izz="3.125e-05" />
    </inertial>
    </link>

    <joint name="${prefix}gripper_joint" type="revolute">
      <limit effort="60" lower="0" upper="0.1" velocity="0.05" /><dynamics damping="100.0" />
      <axis xyz="0 0 1" />
      <origin xyz="0 0.102 0" rpy="${pi/-2.0} 0 0"/>
      <parent link="${prefix}wrist_3_link"/>
      <child link="${prefix}gripper_link"/>-
    </joint>

   
   
   <transmission name="${prefix}gripper_control">
    <type>transmission_interface/SimpleTransmission</type>
    <joint name="${prefix}gripper_joint">
     <hardwareInterface>hardware_interface/PositionJointInterface</hardwareInterface>
    </joint>
    <actuator name="${prefix}gripper_motor">
     <hardwareInterface>hardware_interface/PositionJointInterface</hardwareInterface>
     <mechanicalReduction>2</mechanicalReduction>
    </actuator>
   </transmission>-->
  <link name="ur5_left_link5">
    <visual>
      <origin rpy="0 0 0" xyz="0 0 0"/>
      <geometry>
        <mesh filename="package://neo_simulation/robots/mpo_500/meshes/ur5/visual/link5.stl" scale="0.5 0.5 0.5"/>
      </geometry>
      <material name="light_grey">
        <color rgba="0.7 0.7 0.7 1.0"/>
      </material>
    </visual>
    <collision>
      <origin rpy="0 0 0" xyz="0 0 0"/>
      <geometry>
        <mesh filename="package://neo_simulation/robots/mpo_500/meshes/ur5/visual/link5.stl" scale="0.5 0.5 0.5"/>
      </geometry>
    </collision>
    <inertial>
      <origin rpy="0 0 0" xyz="0.0 0.0 0.0"/>
      <mass value="0.7"/>
      <inertia ixx="0.0003529" ixy="-0" ixz="0" iyy="0.0007598" iyz="-0" izz="0.0007598"/>
    </inertial>
  </link>
  <link name="ur5_left_finger1">
    <visual>
      <origin rpy="0 0 0" xyz="0 0 0"/>
      <geometry>
        <mesh filename="package://neo_simulation/robots/mpo_500/meshes/ur5/visual/fin1.stl" scale="0.5 0.5 0.5"/>
      </geometry>
      <material name="light_grey">
        <color rgba="0.7 0.7 0.7 1.0"/>
      </material>
    </visual>
    <collision>
      <origin rpy="0 0 0" xyz="0 0 0"/>
      <geometry>
        <mesh filename="package://neo_simulation/robots/mpo_500/meshes/ur5/visual/fin1.stl" scale="0.5 0.5 0.5"/>
      </geometry>
    </collision>
    <inertial>
      <origin rpy="0 0 0.15" xyz="-0.015 0.07 0.0"/>
      <mass value="0.7"/>
      <inertia ixx="0.001607" ixy="0" ixz="-0" iyy="0.00005536" iyz="-0" izz="0.0016246"/>
    </inertial>
  </link>
  <link name="ur5_left_finger2">
    <visual>
      <origin rpy="0 0 0" xyz="0 0 0"/>
      <geometry>
        <mesh filename="package://neo_simulation/robots/mpo_500/meshes/ur5/visual/fin2.stl" scale="0.5 0.5 0.5"/>
      </geometry>
      <material name="light_grey">
        <color rgba="0.7 0.7 0.7 1.0"/>
      </material>
    </visual>
    <collision>
      <origin rpy="0 0 0" xyz="0 0 0"/>
      <geometry>
        <mesh filename="package://neo_simulation/robots/mpo_500/meshes/ur5/visual//fin2.stl" scale="0.5 0.5 0.5"/>
      </geometry>
    </collision>
    <inertial>
      <origin rpy="0 0 -0.15" xyz="0.015 0.07 0.0"/>
      <mass value="0.7"/>
      <inertia ixx="0.001607" ixy="0" ixz="-0" iyy="0.00005536" iyz="-0" izz="0.0016246"/>
    </inertial>
  </link>
  <joint name="ur5_left_link5_joint" type="fixed">
    <parent link="ur5_left_ee_link"/>
    <child link="ur5_left_link5"/>
    <origin rpy="1.5708 0 1.5708" xyz="0 0 0"/>
    <!--<limit lower= "-3.0" upper= "3.0" effort="200" velocity="3" />
    <axis xyz = "0 0 1" />-->
  </joint>
  <joint name="ur5_left_l_finger_joint" type="prismatic">
    <origin rpy="1.5708 0 0" xyz="0.040 0 0.038"/>
    <parent link="ur5_left_link5"/>
    <child link="ur5_left_finger1"/>
    <axis xyz="1 0 0"/>
    <limit effort="60" lower="0" upper="0.1" velocity="3"/>
    <dynamics damping="100.0"/>
  </joint>
  <joint name="ur5_left_r_finger_joint" type="prismatic">
    <origin rpy="1.5708 0 0" xyz="-0.040 0 0.038"/>
    <parent link="ur5_left_link5"/>
    <child link="ur5_left_finger2"/>
    <axis xyz="-1 0 0"/>
    <limit effort="60" lower="0" upper="0.1" velocity="3"/>
    <dynamics damping="100.0"/>
  </joint>
  <gazebo reference="ur5_left_link5">
    <mu1>5.0</mu1>
    <mu2>5.0</mu2>
    <material>Gazebo/Grey</material>
    <turnGravityOff>false</turnGravityOff>
  </gazebo>
  <gazebo reference="ur5_left_finger1">
    <implicitSpringDamper>1</implicitSpringDamper>
    <kp>1000000.0</kp>
    <kd>1.0</kd>
    <mu1>10000.0</mu1>
    <mu2>10000.0</mu2>
    <minDepth>0.001</minDepth>
    <material>Gazebo/Grey</material>
    <turnGravityOff>false</turnGravityOff>
  </gazebo>
  <gazebo reference="ur5_left_finger2">
    <implicitSpringDamper>1</implicitSpringDamper>
    <kp>1000000.0</kp>
    <kd>1.0</kd>
    <mu1>100000</mu1>
    <mu2>100000</mu2>
    <minDepth>0.001</minDepth>
    <material>Gazebo/Grey</material>
    <turnGravityOff>false</turnGravityOff>
  </gazebo>
  <!--<transmission name="${prefix}link5_control">
    <type>transmission_interface/SimpleTransmission</type>
    <joint name="${prefix}link5_joint">
     <hardwareInterface>hardware_interface/PositionJointInterface</hardwareInterface>
    </joint>
    <actuator name="${prefix}link5_motor">
     <hardwareInterface>hardware_interface/PositionJointInterface</hardwareInterface>
     <mechanicalReduction>2</mechanicalReduction>
    </actuator>
</transmission>-->
  <transmission name="ur5_left_link5_finger1_control">
    <type>transmission_interface/SimpleTransmission</type>
    <joint name="ur5_left_l_finger_joint">
      <hardwareInterface>hardware_interface/PositionJointInterface</hardwareInterface>
    </joint>
    <actuator name="ur5_left_l_finger_motor">
      <hardwareInterface>hardware_interface/PositionJointInterface</hardwareInterface>
      <mechanicalReduction>2</mechanicalReduction>
    </actuator>
  </transmission>
  <transmission name="ur5_left_link5_finger2_control">
    <type>transmission_interface/SimpleTransmission</type>
    <joint name="ur5_left_r_finger_joint">
      <hardwareInterface>hardware_interface/PositionJointInterface</hardwareInterface>
    </joint>
    <actuator name="ur5_left_r_finger_motor">
      <hardwareInterface>hardware_interface/PositionJointInterface</hardwareInterface>
      <mechanicalReduction>2</mechanicalReduction>
    </actuator>
  </transmission>
  <!--<xacro:robotiq_arg2f_85 prefix="lgripper_"/>
    <joint name="lgripper_left_joint" type="fixed">
       <parent link="ur5_left_tool0"/>
       <child link="lgripper_robotiq_arg2f_base_link"/>
       <origin xyz="0 0 0" rpy="0 0 0"/>
    </joint>-->
  <!--<xacro:robotiq_85_gripper prefix="lgripper_" parent="ur5_left_tool0" >
        <origin xyz="0.0 0 0.0" rpy="0 -1.5708 0"/>
    </xacro:robotiq_85_gripper>  -->
  <!-- measured from model -->
  <!--property name="shoulder_height" value="0.089159" /-->
  <!--property name="shoulder_offset" value="0.13585" /-->
  <!-- shoulder_offset - elbow_offset + wrist_1_length = 0.10915 -->
  <!--property name="upper_arm_length" value="0.42500" /-->
  <!--property name="elbow_offset" value="0.1197" /-->
  <!-- CAD measured -->
  <!--property name="forearm_length" value="0.39225" /-->
  <!--property name="wrist_1_length" value="0.093" /-->
  <!-- CAD measured -->
  <!--property name="wrist_2_length" value="0.09465" /-->
  <!-- In CAD this distance is 0.930, but in the spec it is 0.09465 -->
  <!--property name="wrist_3_length" value="0.0823" /-->
  <!-- manually measured -->
  <joint name="ur5_right_joint" type="fixed">
    <parent link="shoulder_link"/>
    <child link="ur5_right_base_link"/>
    <!--<origin xyz="0.0 0.28 -0.005" rpy="0 -3.14159 0" />-->
    <origin rpy="0 -3.14159 3.14159" xyz="0.0 -0.28 -0.005"/>
  </joint>
  <link name="ur5_right_base_link">
    <visual>
      <geometry>
        <mesh filename="package://neo_simulation/robots/mpo_500/meshes/ur5/visual/base.dae"/>
      </geometry>
      <material name="LightGrey">
        <color rgba="0.7 0.7 0.7 1.0"/>
      </material>
    </visual>
    <collision>
      <geometry>
        <mesh filename="package://neo_simulation/robots/mpo_500/meshes/ur5/collision/base.stl"/>
      </geometry>
    </collision>
    <inertial>
      <mass value="4.0"/>
      <origin rpy="0 0 0" xyz="0.0 0.0 0.0"/>
      <inertia ixx="0.00443333156" ixy="0.0" ixz="0.0" iyy="0.00443333156" iyz="0.0" izz="0.0072"/>
    </inertial>
  </link>
  <joint name="ur5_right_shoulder_pan_joint" type="revolute">
    <parent link="ur5_right_base_link"/>
    <child link="ur5_right_shoulder_link"/>
    <origin rpy="0.0 0.0 0.0" xyz="0.0 0.0 0.089159"/>
    <axis xyz="0 0 1"/>
    <limit effort="150.0" lower="-3.14159265359" upper="3.14159265359" velocity="3.15"/>
    <dynamics damping="0.0" friction="0.0"/>
  </joint>
  <link name="ur5_right_shoulder_link">
    <visual>
      <geometry>
        <mesh filename="package://neo_simulation/robots/mpo_500/meshes/ur5/visual/shoulder.dae"/>
      </geometry>
      <material name="LightGrey">
        <color rgba="0.7 0.7 0.7 1.0"/>
      </material>
    </visual>
    <collision>
      <geometry>
        <mesh filename="package://neo_simulation/robots/mpo_500/meshes/ur5/collision/shoulder.stl"/>
      </geometry>
    </collision>
    <inertial>
      <mass value="3.7"/>
      <origin rpy="0 0 0" xyz="0.0 0.0 0.0"/>
      <inertia ixx="0.010267495893" ixy="0.0" ixz="0.0" iyy="0.010267495893" iyz="0.0" izz="0.00666"/>
    </inertial>
  </link>
  <joint name="ur5_right_shoulder_lift_joint" type="revolute">
    <parent link="ur5_right_shoulder_link"/>
    <child link="ur5_right_upper_arm_link"/>
    <origin rpy="0.0 0 0.0" xyz="0.0 0.13585 0.0"/>
    <axis xyz="0 1 0"/>
    <limit effort="150.0" lower="-3.14159265359" upper="3.14159265359" velocity="3.15"/>
    <dynamics damping="0.0" friction="0.0"/>
  </joint>
  <link name="ur5_right_upper_arm_link">
    <visual>
      <geometry>
        <mesh filename="package://neo_simulation/robots/mpo_500/meshes/ur5/visual/upperarm.dae"/>
      </geometry>
      <material name="LightGrey">
        <color rgba="0.7 0.7 0.7 1.0"/>
      </material>
    </visual>
    <collision>
      <geometry>
        <mesh filename="package://neo_simulation/robots/mpo_500/meshes/ur5/collision/upperarm.stl"/>
      </geometry>
    </collision>
    <inertial>
      <mass value="8.393"/>
      <origin rpy="0 0 0" xyz="0.0 0.0 0.28"/>
      <inertia ixx="0.22689067591" ixy="0.0" ixz="0.0" iyy="0.22689067591" iyz="0.0" izz="0.0151074"/>
    </inertial>
  </link>
  <joint name="ur5_right_elbow_joint" type="revolute">
    <parent link="ur5_right_upper_arm_link"/>
    <child link="ur5_right_forearm_link"/>
    <origin rpy="0.0 0.0 0.0" xyz="0.0 -0.1197 0.425"/>
    <!--1.25-->
    <axis xyz="0 1 0"/>
    <limit effort="150.0" lower="0" upper="3.14159265359" velocity="3.15"/>
    <dynamics damping="0.0" friction="0.0"/>
  </joint>
  <link name="ur5_right_forearm_link">
    <visual>
      <geometry>
        <mesh filename="package://neo_simulation/robots/mpo_500/meshes/ur5/visual/forearm.dae"/>
      </geometry>
      <material name="LightGrey">
        <color rgba="0.7 0.7 0.7 1.0"/>
      </material>
    </visual>
    <collision>
      <geometry>
        <mesh filename="package://neo_simulation/robots/mpo_500/meshes/ur5/collision/forearm.stl"/>
      </geometry>
    </collision>
    <inertial>
      <mass value="2.275"/>
      <origin rpy="0 0 0" xyz="0.0 0.0 0.196125"/>
      <inertia ixx="0.0312167910289" ixy="0.0" ixz="0.0" iyy="0.0312167910289" iyz="0.0" izz="0.004095"/>
    </inertial>
  </link>
  <joint name="ur5_right_wrist_1_joint" type="revolute">
    <parent link="ur5_right_forearm_link"/>
    <child link="ur5_right_wrist_1_link"/>
    <origin rpy="0.0 0.0 0.0" xyz="0.0 0.0 0.39225"/>
    <axis xyz="0 1 0"/>
    <limit effort="28.0" lower="-3.14159265359" upper="3.14159265359" velocity="3.2"/>
    <dynamics damping="0.0" friction="0.0"/>
  </joint>
  <link name="ur5_right_wrist_1_link">
    <visual>
      <geometry>
        <mesh filename="package://neo_simulation/robots/mpo_500/meshes/ur5/visual/wrist1.dae"/>
      </geometry>
      <material name="LightGrey">
        <color rgba="0.7 0.7 0.7 1.0"/>
      </material>
    </visual>
    <collision>
      <geometry>
        <mesh filename="package://neo_simulation/robots/mpo_500/meshes/ur5/collision/wrist1.stl"/>
      </geometry>
    </collision>
    <inertial>
      <mass value="1.219"/>
      <origin rpy="0 0 0" xyz="0.0 0.093 0.0"/>
      <inertia ixx="0.00255989897604" ixy="0.0" ixz="0.0" iyy="0.00255989897604" iyz="0.0" izz="0.0021942"/>
    </inertial>
  </link>
  <joint name="ur5_right_wrist_2_joint" type="revolute">
    <parent link="ur5_right_wrist_1_link"/>
    <child link="ur5_right_wrist_2_link"/>
    <origin rpy="0.0 0.0 -1.5708" xyz="0.0 0.093 0.0"/>
    <axis xyz="0 0 1"/>
    <limit effort="28.0" lower="-3.14159265359" upper="3.14159265359" velocity="3.2"/>
    <dynamics damping="0.0" friction="0.0"/>
  </joint>
  <link name="ur5_right_wrist_2_link">
    <visual>
      <geometry>
        <mesh filename="package://neo_simulation/robots/mpo_500/meshes/ur5/visual/wrist2.dae"/>
      </geometry>
      <material name="LightGrey">
        <color rgba="0.7 0.7 0.7 1.0"/>
      </material>
    </visual>
    <collision>
      <geometry>
        <mesh filename="package://neo_simulation/robots/mpo_500/meshes/ur5/collision/wrist2.stl"/>
      </geometry>
    </collision>
    <inertial>
      <mass value="1.219"/>
      <origin rpy="0 0 0" xyz="0.0 0.0 0.09465"/>
      <inertia ixx="0.00255989897604" ixy="0.0" ixz="0.0" iyy="0.00255989897604" iyz="0.0" izz="0.0021942"/>
    </inertial>
  </link>
  <joint name="ur5_right_wrist_3_joint" type="revolute">
    <parent link="ur5_right_wrist_2_link"/>
    <child link="ur5_right_wrist_3_link"/>
    <origin rpy="0.0 0.0 0.0" xyz="0.0 0.0 0.09465"/>
    <axis xyz="0 1 0"/>
    <limit effort="28.0" lower="-3.14159265359" upper="3.14159265359" velocity="3.2"/>
    <dynamics damping="0.0" friction="0.0"/>
  </joint>
  <link name="ur5_right_wrist_3_link">
    <visual>
      <geometry>
        <mesh filename="package://neo_simulation/robots/mpo_500/meshes/ur5/visual/wrist3.dae"/>
      </geometry>
      <material name="LightGrey">
        <color rgba="0.7 0.7 0.7 1.0"/>
      </material>
    </visual>
    <collision>
      <geometry>
        <mesh filename="package://neo_simulation/robots/mpo_500/meshes/ur5/collision/wrist3.stl"/>
      </geometry>
    </collision>
    <inertial>
      <mass value="0.1879"/>
      <origin rpy="1.57079632679 0 0" xyz="0.0 0.06505 0.0"/>
      <inertia ixx="8.46958911216e-05" ixy="0.0" ixz="0.0" iyy="8.46958911216e-05" iyz="0.0" izz="0.0001321171875"/>
    </inertial>
  </link>
  <joint name="ur5_right_ee_fixed_joint" type="fixed">
    <parent link="ur5_right_wrist_3_link"/>
    <child link="ur5_right_ee_link"/>
    <origin rpy="0.0 0.0 1.57079632679" xyz="0.0 0.0823 0.0"/>
  </joint>
  <link name="ur5_right_ee_link">
    <collision>
      <geometry>
        <box size="0.01 0.01 0.01"/>
      </geometry>
      <origin rpy="0 0 0" xyz="-0.01 0 0"/>
    </collision>
  </link>
  <transmission name="ur5_right_shoulder_pan_trans">
    <type>transmission_interface/SimpleTransmission</type>
    <joint name="ur5_right_shoulder_pan_joint">
      <hardwareInterface>hardware_interface/PositionJointInterface</hardwareInterface>
    </joint>
    <actuator name="ur5_right_shoulder_pan_motor">
      <mechanicalReduction>1</mechanicalReduction>
    </actuator>
  </transmission>
  <transmission name="ur5_right_shoulder_lift_trans">
    <type>transmission_interface/SimpleTransmission</type>
    <joint name="ur5_right_shoulder_lift_joint">
      <hardwareInterface>hardware_interface/PositionJointInterface</hardwareInterface>
    </joint>
    <actuator name="ur5_right_shoulder_lift_motor">
      <mechanicalReduction>1</mechanicalReduction>
    </actuator>
  </transmission>
  <transmission name="ur5_right_elbow_trans">
    <type>transmission_interface/SimpleTransmission</type>
    <joint name="ur5_right_elbow_joint">
      <hardwareInterface>hardware_interface/PositionJointInterface</hardwareInterface>
    </joint>
    <actuator name="ur5_right_elbow_motor">
      <mechanicalReduction>1</mechanicalReduction>
    </actuator>
  </transmission>
  <transmission name="ur5_right_wrist_1_trans">
    <type>transmission_interface/SimpleTransmission</type>
    <joint name="ur5_right_wrist_1_joint">
      <hardwareInterface>hardware_interface/PositionJointInterface</hardwareInterface>
    </joint>
    <actuator name="ur5_right_wrist_1_motor">
      <mechanicalReduction>1</mechanicalReduction>
    </actuator>
  </transmission>
  <transmission name="ur5_right_wrist_2_trans">
    <type>transmission_interface/SimpleTransmission</type>
    <joint name="ur5_right_wrist_2_joint">
      <hardwareInterface>hardware_interface/PositionJointInterface</hardwareInterface>
    </joint>
    <actuator name="ur5_right_wrist_2_motor">
      <mechanicalReduction>1</mechanicalReduction>
    </actuator>
  </transmission>
  <transmission name="ur5_right_wrist_3_trans">
    <type>transmission_interface/SimpleTransmission</type>
    <joint name="ur5_right_wrist_3_joint">
      <hardwareInterface>hardware_interface/PositionJointInterface</hardwareInterface>
    </joint>
    <actuator name="ur5_right_wrist_3_motor">
      <mechanicalReduction>1</mechanicalReduction>
    </actuator>
  </transmission>
  <gazebo reference="ur5_right_shoulder_link">
    <selfCollide>true</selfCollide>
  </gazebo>
  <gazebo reference="ur5_right_upper_arm_link">
    <selfCollide>true</selfCollide>
  </gazebo>
  <gazebo reference="ur5_right_forearm_link">
    <selfCollide>true</selfCollide>
  </gazebo>
  <gazebo reference="ur5_right_wrist_1_link">
    <selfCollide>true</selfCollide>
  </gazebo>
  <gazebo reference="ur5_right_wrist_3_link">
    <selfCollide>true</selfCollide>
  </gazebo>
  <gazebo reference="ur5_right_wrist_2_link">
    <selfCollide>true</selfCollide>
  </gazebo>
  <gazebo reference="ur5_right_ee_link">
    <selfCollide>true</selfCollide>
  </gazebo>
  <!-- ROS base_link to UR 'Base' Coordinates transform -->
  <!-- NOTE: this rotation is only needed as long as base_link itself is
                 not corrected wrt the real robot (ie: rotated over 180
                 degrees)
      -->
  <!-- <link name="${prefix}base"/>
    <joint name="${prefix}base_link-base_fixed_joint" type="fixed">
     
      <origin xyz="0 0 0" rpy="0 0 ${-pi}"/>
      <parent link="${prefix}base_link"/>
      <child link="${prefix}base"/>
    </joint>-->
  <!-- Frame coincident with all-zeros TCP on UR controller -->
  <link name="ur5_right_tool0"/>
  <joint name="ur5_right_wrist_3_link-tool0_fixed_joint" type="fixed">
    <origin rpy="-3.14159265359 0 1.57079632679" xyz="0 0.2683 0"/>
    <parent link="ur5_right_wrist_3_link"/>
    <child link="ur5_right_tool0"/>
  </joint>
  <!--<link name="${prefix}tool_link"0.3183 0.2683 0.2483/>
    <joint name="${prefix}tool_joint" type="fixed">
      <parent link="${prefix}tool0"/>
      <child link="${prefix}tool_link"/>
      <origin xyz="0 0 0.18" rpy="3.14159 -1.5708 0"/>   
    </joint>-->
  <!--<link name="${prefix}gripper_link">
      <visual>
        <geometry>
          <cylinder radius="0.025" length="0.040" />
        </geometry>
        <material name="LightGrey">
          <color rgba="0.7 0.7 0.7 1.0"/>
        </material>
      </visual>
      <collision>
        <geometry>
           <cylinder radius="0.025" length="0.040" />
        </geometry>
      </collision>
      <inertial>
        <origin xyz="0 0 0" rpy="0 0 0" />
        <mass value= "0.1"/>
        <inertia ixx=" 2.89583333333e-05" ixy="0" ixz="0" iyx="0" iyy="2.89583333333e-05" iyz="0" izx="0" izy="0" izz="3.125e-05" />
    </inertial>
    </link>

    <joint name="${prefix}gripper_joint" type="revolute">
      <limit effort="60" lower="0" upper="0.1" velocity="0.05" /><dynamics damping="100.0" />
      <axis xyz="0 0 1" />
      <origin xyz="0 0.102 0" rpy="${pi/-2.0} 0 0"/>
      <parent link="${prefix}wrist_3_link"/>
      <child link="${prefix}gripper_link"/>-
    </joint>

   
   
   <transmission name="${prefix}gripper_control">
    <type>transmission_interface/SimpleTransmission</type>
    <joint name="${prefix}gripper_joint">
     <hardwareInterface>hardware_interface/PositionJointInterface</hardwareInterface>
    </joint>
    <actuator name="${prefix}gripper_motor">
     <hardwareInterface>hardware_interface/PositionJointInterface</hardwareInterface>
     <mechanicalReduction>2</mechanicalReduction>
    </actuator>
   </transmission>-->
  <link name="ur5_right_link5">
    <visual>
      <origin rpy="0 0 0" xyz="0 0 0"/>
      <geometry>
        <mesh filename="package://neo_simulation/robots/mpo_500/meshes/ur5/visual/link5.stl" scale="0.5 0.5 0.5"/>
      </geometry>
      <material name="light_grey">
        <color rgba="0.7 0.7 0.7 1.0"/>
      </material>
    </visual>
    <collision>
      <origin rpy="0 0 0" xyz="0 0 0"/>
      <geometry>
        <mesh filename="package://neo_simulation/robots/mpo_500/meshes/ur5/visual/link5.stl" scale="0.5 0.5 0.5"/>
      </geometry>
    </collision>
    <inertial>
      <origin rpy="0 0 0" xyz="0.0 0.0 0.0"/>
      <mass value="0.7"/>
      <inertia ixx="0.0003529" ixy="-0" ixz="0" iyy="0.0007598" iyz="-0" izz="0.0007598"/>
    </inertial>
  </link>
  <link name="ur5_right_finger1">
    <visual>
      <origin rpy="0 0 0" xyz="0 0 0"/>
      <geometry>
        <mesh filename="package://neo_simulation/robots/mpo_500/meshes/ur5/visual/fin1.stl" scale="0.5 0.5 0.5"/>
      </geometry>
      <material name="light_grey">
        <color rgba="0.7 0.7 0.7 1.0"/>
      </material>
    </visual>
    <collision>
      <origin rpy="0 0 0" xyz="0 0 0"/>
      <geometry>
        <mesh filename="package://neo_simulation/robots/mpo_500/meshes/ur5/visual/fin1.stl" scale="0.5 0.5 0.5"/>
      </geometry>
    </collision>
    <inertial>
      <origin rpy="0 0 0.15" xyz="-0.015 0.07 0.0"/>
      <mass value="0.7"/>
      <inertia ixx="0.001607" ixy="0" ixz="-0" iyy="0.00005536" iyz="-0" izz="0.0016246"/>
    </inertial>
  </link>
  <link name="ur5_right_finger2">
    <visual>
      <origin rpy="0 0 0" xyz="0 0 0"/>
      <geometry>
        <mesh filename="package://neo_simulation/robots/mpo_500/meshes/ur5/visual/fin2.stl" scale="0.5 0.5 0.5"/>
      </geometry>
      <material name="light_grey">
        <color rgba="0.7 0.7 0.7 1.0"/>
      </material>
    </visual>
    <collision>
      <origin rpy="0 0 0" xyz="0 0 0"/>
      <geometry>
        <mesh filename="package://neo_simulation/robots/mpo_500/meshes/ur5/visual//fin2.stl" scale="0.5 0.5 0.5"/>
      </geometry>
    </collision>
    <inertial>
      <origin rpy="0 0 -0.15" xyz="0.015 0.07 0.0"/>
      <mass value="0.7"/>
      <inertia ixx="0.001607" ixy="0" ixz="-0" iyy="0.00005536" iyz="-0" izz="0.0016246"/>
    </inertial>
  </link>
  <joint name="ur5_right_link5_joint" type="fixed">
    <parent link="ur5_right_ee_link"/>
    <child link="ur5_right_link5"/>
    <origin rpy="1.5708 0 1.5708" xyz="0 0 0"/>
    <!--<limit lower= "-3.0" upper= "3.0" effort="200" velocity="3" />
    <axis xyz = "0 0 1" />-->
  </joint>
  <joint name="ur5_right_l_finger_joint" type="prismatic">
    <origin rpy="1.5708 0 0" xyz="0.040 0 0.038"/>
    <parent link="ur5_right_link5"/>
    <child link="ur5_right_finger1"/>
    <axis xyz="1 0 0"/>
    <limit effort="60" lower="0" upper="0.1" velocity="3"/>
    <dynamics damping="100.0"/>
  </joint>
  <joint name="ur5_right_r_finger_joint" type="prismatic">
    <origin rpy="1.5708 0 0" xyz="-0.040 0 0.038"/>
    <parent link="ur5_right_link5"/>
    <child link="ur5_right_finger2"/>
    <axis xyz="-1 0 0"/>
    <limit effort="60" lower="0" upper="0.1" velocity="3"/>
    <dynamics damping="100.0"/>
  </joint>
  <gazebo reference="ur5_right_link5">
    <mu1>5.0</mu1>
    <mu2>5.0</mu2>
    <material>Gazebo/Grey</material>
    <turnGravityOff>false</turnGravityOff>
  </gazebo>
  <gazebo reference="ur5_right_finger1">
    <implicitSpringDamper>1</implicitSpringDamper>
    <kp>1000000.0</kp>
    <kd>1.0</kd>
    <mu1>10000.0</mu1>
    <mu2>10000.0</mu2>
    <minDepth>0.001</minDepth>
    <material>Gazebo/Grey</material>
    <turnGravityOff>false</turnGravityOff>
  </gazebo>
  <gazebo reference="ur5_right_finger2">
    <implicitSpringDamper>1</implicitSpringDamper>
    <kp>1000000.0</kp>
    <kd>1.0</kd>
    <mu1>100000</mu1>
    <mu2>100000</mu2>
    <minDepth>0.001</minDepth>
    <material>Gazebo/Grey</material>
    <turnGravityOff>false</turnGravityOff>
  </gazebo>
  <!--<transmission name="${prefix}link5_control">
    <type>transmission_interface/SimpleTransmission</type>
    <joint name="${prefix}link5_joint">
     <hardwareInterface>hardware_interface/PositionJointInterface</hardwareInterface>
    </joint>
    <actuator name="${prefix}link5_motor">
     <hardwareInterface>hardware_interface/PositionJointInterface</hardwareInterface>
     <mechanicalReduction>2</mechanicalReduction>
    </actuator>
</transmission>-->
  <transmission name="ur5_right_link5_finger1_control">
    <type>transmission_interface/SimpleTransmission</type>
    <joint name="ur5_right_l_finger_joint">
      <hardwareInterface>hardware_interface/PositionJointInterface</hardwareInterface>
    </joint>
    <actuator name="ur5_right_l_finger_motor">
      <hardwareInterface>hardware_interface/PositionJointInterface</hardwareInterface>
      <mechanicalReduction>2</mechanicalReduction>
    </actuator>
  </transmission>
  <transmission name="ur5_right_link5_finger2_control">
    <type>transmission_interface/SimpleTransmission</type>
    <joint name="ur5_right_r_finger_joint">
      <hardwareInterface>hardware_interface/PositionJointInterface</hardwareInterface>
    </joint>
    <actuator name="ur5_right_r_finger_motor">
      <hardwareInterface>hardware_interface/PositionJointInterface</hardwareInterface>
      <mechanicalReduction>2</mechanicalReduction>
    </actuator>
  </transmission>
  <!-- left gripper -->
  <!--<xacro:robotiq_arg2f_140 prefix="lgripper_"/>
            <joint name="lgripper_left_joint" type="fixed">
                <parent link="left_tool0"/>
                <child link="lgripper_robotiq_arg2f_base_link"/>
                <origin xyz="0 0 0" rpy="0 0 0"/>
            </joint>
        </xacro:if>-->
  <!-- right gripper -->
  <!--  <xacro:robotiq_arg2f_140 prefix="rgripper_"/>
            <joint name="rgripper_right_joint" type="fixed">
                <parent link="ur5_right_ee_link"/>
                <child link="rgripper_robotiq_arg2f_base_link"/>
                <origin xyz="0 0 0" rpy="1.5708 1.5708 1.5708"/>
            </joint>-->
  <!--<xacro:robotiq_arg2f_85 prefix="rgripper_"/>
            <joint name="rgripper_right_joint" type="fixed">
                <parent link="ur5_right_tool0"/>
                <child link="rgripper_robotiq_arg2f_base_link"/>
                <origin xyz="0 0 0" rpy="0 0 0"/>
            </joint>-->
  <!--<xacro:robotiq_85_gripper prefix="rgripper_" parent="ur5_right_tool0" >
        <origin xyz="0.0 0 0.0" rpy="0 -1.5708 0"/>
    </xacro:robotiq_85_gripper> -->
  <!--<gazebo>
   <plugin name="gazebo_grasp_fix" filename="libgazebo_grasp_fix.so">
        <arm>
           <arm_name>mpo_500</arm_name>
           <palm_link>ur5_right_wrist_3_link</palm_link>
           <gripper_link>rgripper_left_inner_finger</gripper_link>
           <gripper_link>rgripper_right_inner_finger</gripper_link>
        </arm>
       <forces_angle_tolerance>100</forces_angle_tolerance>
       <update_rate>4</update_rate>
       <grip_count_threshold>2</grip_count_threshold>
       <max_grip_count>4</max_grip_count>
       <release_tolerance>0.005</release_tolerance>
       <disable_collisions_on_attach>true</disable_collisions_on_attach>
       <contact_topic>__default_topic__</contact_topic>
    </plugin>
   </gazebo>-->
  <!--<transmission name="${prefix}gripper_control">
    <type>transmission_interface/SimpleTransmission</type>
    <joint name="${prefix}gripper_joint">
     <hardwareInterface>hardware_interface/PositionJointInterface</hardwareInterface>
    </joint>
    <actuator name="${prefix}gripper_motor">
     <hardwareInterface>hardware_interface/PositionJointInterface</hardwareInterface>
     <mechanicalReduction>2</mechanicalReduction>
    </actuator>
   </transmission>-->
  <!--<gazebo>
   <plugin name="gazebo_grasp_fix" filename="libgazebo_grasp_fix.so">
        <arm>
           <arm_name>mpo_500</arm_name>
           <palm_link>ur5_left_wrist_3_link</palm_link>
           <gripper_link>ur5_left_gripper_link</gripper_link>
        </arm>
       <forces_angle_tolerance>100</forces_angle_tolerance>
       <update_rate>4</update_rate>
       <grip_count_threshold>2</grip_count_threshold>
       <max_grip_count>4</max_grip_count>
       <release_tolerance>0.005</release_tolerance>
       <disable_collisions_on_attach>true</disable_collisions_on_attach>
       <contact_topic>__default_topic__</contact_topic>
    </plugin>
   </gazebo>-->
  <gazebo>
    <plugin filename="libgazebo_grasp_fix.so" name="gazebo_grasp_fix">
      <arm>
        <arm_name>mpo_500</arm_name>
        <palm_link>ur5_left_wrist_3_link</palm_link>
        <gripper_link>ur5_left_finger1</gripper_link>
        <gripper_link>ur5_left_finger2</gripper_link>
      </arm>
      <forces_angle_tolerance>100</forces_angle_tolerance>
      <update_rate>1000</update_rate>
      <grip_count_threshold>1</grip_count_threshold>
      <max_grip_count>2</max_grip_count>
      <release_tolerance>0.005</release_tolerance>
      <disable_collisions_on_attach>true</disable_collisions_on_attach>
      <contact_topic>__default_topic__</contact_topic>
    </plugin>
  </gazebo>
  <transmission name="mpo_500_omni_wheel_front_left">
    <type>transmission_interface/SimpleTransmission</type>
    <joint name="mpo_500_omni_wheel_front_left_joint">
      <hardwareInterface>hardware_interface/VelocityJointInterface</hardwareInterface>
    </joint>
    <actuator name="mpo_500_omni_wheel_front_left_motor">
      <mechanicalReduction>1</mechanicalReduction>
    </actuator>
  </transmission>
  <transmission name="mpo_500_omni_wheel_front_right">
    <type>transmission_interface/SimpleTransmission</type>
    <joint name="mpo_500_omni_wheel_front_right_joint">
      <hardwareInterface>hardware_interface/VelocityJointInterface</hardwareInterface>
    </joint>
    <actuator name="mpo_500_omni_wheel_front_right_motor">
      <mechanicalReduction>1</mechanicalReduction>
    </actuator>
  </transmission>
  <transmission name="mpo_500_omni_wheel_back_left">
    <type>transmission_interface/SimpleTransmission</type>
    <joint name="mpo_500_omni_wheel_back_left_joint">
      <hardwareInterface>hardware_interface/VelocityJointInterface</hardwareInterface>
    </joint>
    <actuator name="mpo_500_omni_wheel_back_left_motor">
      <mechanicalReduction>1</mechanicalReduction>
    </actuator>
  </transmission>
  <transmission name="mpo_500_omni_wheel_back_right">
    <type>transmission_interface/SimpleTransmission</type>
    <joint name="mpo_500_omni_wheel_back_right_joint">
      <hardwareInterface>hardware_interface/VelocityJointInterface</hardwareInterface>
    </joint>
    <actuator name="mpo_500_omni_wheel_back_right_motor">
      <mechanicalReduction>1</mechanicalReduction>
    </actuator>
  </transmission>
</robot>
